Workbook

Sheet README
A1: BCS · ไฟล์ข้อมูลตั้งต้น v1 (สำหรับ demo LK-RICH)
A3: ใช้ทำอะไร | B3: ช่วงที่ 1 (ตอนนี้): ข้อมูลสมมติทั้งหมด ใช้ seed แอปสำหรับ demo · ช่วงที่ 2 (หลัง demo): ใช้เป็นแบบฟอร์มเก็บข้อมูลจริงจาก LK-RICH แล้วทำ version 2
A4: ข้อห้าม | B4: ห้ามใส่ข้อมูลจริงของพนักงานหรือตัวเลขจริงของ LK-RICH จนกว่าจะตกลงเรื่องที่ตั้งข้อมูล (OQ-19) · ชื่อและโลโก้บริษัทใส่ได้ถ้าได้รับอนุญาต
A5: ตรวจไฟล์ | B5: python3 validate_inputs.py BCS_inputs_v1_demo.xlsx --spec spec.md (บันทึกไฟล์จาก Excel หรือ LibreOffice ก่อน เพื่อให้มีค่าที่คำนวณแล้วของสูตร)
A7: สัญลักษณ์
A8: หัวคอลัมน์สีน้ำเงินเข้ม | B8: ข้อมูลที่ต้องได้ของจริงจาก LK-RICH ใน version 2
A9: หัวคอลัมน์สีเทา | B9: ค่าที่ BCS ตั้งให้ใน demo เปลี่ยนได้หลังคุยกับลูกค้า
A10: หัวคอลัมน์สีทอง | B10: ใช้เฉพาะ demo
A11: ช่องสีเหลือง | B11: ช่องให้กรอกคำตอบระหว่างประชุม
A12: ตัวอักษรน้ำเงิน / ดำ | B12: น้ำเงิน = ค่าที่พิมพ์ลงไป · ดำ = สูตร ห้ามแก้
A13: โครงตาราง | B13: แถว 1 = ชื่อคอลัมน์สำหรับโปรแกรม (ห้ามแก้) · แถว 2 = คำอธิบายภาษาไทย · ข้อมูลเริ่มแถว 3 · แถวว่างแรกคือจุดสิ้นสุดตาราง
A15: ชีต | B15: ใช้ทำอะไร
A16: Inputs | B16: รายการข้อมูลที่ต้องขอจาก LK-RICH หลัง demo พร้อมค่าที่ใช้ใน demo และสถานะ
A17: Questions | B17: คำถามที่ต้องตัดสินใจ แยกตามการประชุม พร้อมค่าเริ่มต้นที่ใช้ใน demo และช่องคำตอบ
A18: Org | B18: ข้อมูลบริษัท ผู้มีอำนาจลงนาม และ ORG_ADMIN
A19: Departments · Positions · Users | B19: ผังแผนก ตำแหน่งที่มีอำนาจ ผู้ใช้ บทบาท และผู้ดำรงตำแหน่ง
A20: DOA · DOA_Policy | B20: ช่วงวงเงิน ผู้อนุมัติ และนโยบายของฉบับ (ตรงกับ fixture ใน spec §7.4)
... A25: Demo_Script | B25: ลำดับฉาก demo พร้อมยอดเงินที่เลือกให้ชนแต่ละกฎ (demo เท่านั้น)

Sheet Inputs
A1: id | B1: group | C1: item | D1: usedFor | E1: demoValue | F1: provider | G1: neededBefore | H1: ref | I1: sheet | J1: status
A2: รหัส | B2: กลุ่ม | C2: ข้อมูลที่ต้องขอ | D2: ใช้ทำอะไรในระบบ | E2: ค่าที่ใช้ใน demo | F2: ขอจากใคร | G2: ต้องมีก่อนขั้น | H2: อ้างอิง spec | I2: กรอกที่ชีต | J2: สถานะ DEMO รอข้อมูล ได้แล้ว
A3: IN-01 | B3: องค์กร | C3: ชื่อจดทะเบียน เลขผู้เสียภาษี สาขา ที่อยู่ โลโก้ | D3: หัวเอกสาร PR/PO และข้อมูลบริษัท (§6.2) | E3: บริษัท เดโม่ ก่อสร้าง จำกัด (สมมติ) | F3: บัญชี / ธุรการ | G3: S1 | H3: P0-01 | I3: Org | J3: DEMO
A4: IN-02 | B4: องค์กร | C4: ผังองค์กร: สายงาน ฝ่าย แผนก และสายบังคับบัญชา | D4: engine หาผู้อนุมัติโดยไล่ตามผัง (BR-DOA-04) | E4: 7 แผนกสมมติ | F4: HR | G4: S2 | H4: P0-01 | I4: Departments | J4: DEMO
A5: IN-03 | B5: องค์กร | C5: ตำแหน่งที่มีอำนาจอนุมัติ และใครดำรงตำแหน่งแต่ละที่ | D5: ผู้อนุมัติจริงของแต่ละช่วงวงเงิน | E5: DM VP COO CEO PROC_MGR | F5: HR + ผู้บริหาร | G5: S2 | H5: P0-01 | I5: Positions | J5: DEMO
A6: IN-04 | B6: ผู้ใช้ | C6: รายชื่อผู้ใช้: ชื่อ อีเมลบริษัท แผนก บทบาท | D6: สร้างบัญชีและสิทธิ์ (§2.2) | E6: 18 ผู้ใช้สมมติ | F6: HR / IT | G6: S1 | H6: P0-01 | I6: Users | J6: DEMO
A7: IN-05 | B7: ผู้ใช้ | C7: ORG_ADMIN อย่างน้อย 2 คน และผู้มีอำนาจลงนามตามสัญญา | D7: ดูแลระบบและอนุมัติชุดตั้งต้น (BR-DOA-19) | E7: admin admin2 · ceo | F7: ผู้บริหาร | G7: S2 | H7: OQ-31 | I7: Org | J7: DEMO
A8: IN-06 | B8: DOA | C8: เอกสารระเบียบอำนาจอนุมัติฉบับปัจจุบัน | D8: DOA ฉบับแรกของลูกค้า (§7.4) | E8: วงเงินตาม proposal v1.2 | F8: ผู้บริหาร / ตรวจสอบภายใน | G8: S2 | H8: P0-01 | I8: DOA | J8: DEMO
A9: IN-07 | B9: งบ | C9: cost center และรหัสบัญชีค่าใช้จ่าย | D9: ผูกบรรทัดงบกับบัญชีและไฟล์ส่ง Express | E9: รหัสสมมติ | F9: บัญชี | G9: S3 | H9: P0-10 | I9: Budget | J9: DEMO
A10: IN-08 | B10: งบ | C10: งบประมาณปีนี้รายแผนกหรือรายบรรทัด (Excel) | D10: คุมงบก่อนถึงผู้อนุมัติ (BR-BUD-02) | E10: 5 บรรทัด รวม 2,950,000 บาท | F10: บัญชี / งบประมาณ | G10: S3 | H10: OQ-11 | I10: Budget | J10: DEMO
A11: IN-09 | B11: ผู้ขาย | C11: รายชื่อผู้ขายที่ใช้บ่อย: ชื่อ เลขผู้เสียภาษี สาขา จด VAT อีเมล | D11: ออก PO และส่งอีเมล | E11: 5 รายสมมติ | F11: จัดซื้อ | G11: S4 | H11: OQ-22 | I11: Suppliers | J11: DEMO
A12: IN-10 | B12: จัดซื้อ | C12: สถานที่ส่งของและไซต์งานที่เปิดอยู่ | D12: รวม PR ตามสถานที่ส่ง (BR-CONS-01) | E12: 3 แห่งสมมติ | F12: จัดซื้อ / ก่อสร้าง | G12: S4 | H12: OQ-13 | I12: Sites | J12: DEMO
... A27: IN-25 | B27: PDPA | C27: แม่แบบข้อตกลงการประมวลผลข้อมูล (DPA) ของบริษัท | D27: กฎ ATT-DPA (BR-FORM-05) | E27: ยังไม่มี | F27: กฎหมาย / DPO | G27: S2 | H27: BR-FORM-05 | I27: - | J27: รอข้อมูล

Sheet Questions
A1: id | B1: meeting | C1: askWhom | D1: question | E1: whyItMatters | F1: demoDefault | G1: ref | H1: answer | I1: docsToRequest
A2: รหัส | B2: ประชุม A ผู้บริหาร B จัดซื้อ C บัญชี D หน้างาน E IT HR กฎหมาย BCS ภายใน | C2: ถามใคร | D2: คำถาม | E2: มีผลกับอะไร | F2: ค่าที่ใช้ใน demo | G2: อ้างอิง spec | H2: คำตอบ (กรอกระหว่างประชุม) | I2: เอกสารที่ขอ
A3: Q-01 | B3: A | C3: CEO COO CFO | D3: อำนาจอนุมัติแต่ละช่วงวงเงินคือคนเดียว หรือต้องผ่านเป็นสาย (เช่น 50,000 ผ่าน DM แล้ว VP) และถ้าเป็นสาย คนเดียวกันปรากฏสองขั้นให้รวมไหม | E3: เปลี่ยนโครง DOA ทั้งหมด | F3: คนเดียวต่อช่วงตาม proposal · รวมขั้นซ้ำ | G3: OQ-01 OQ-05 | I3: เอกสารระเบียบอำนาจอนุมัติ
A4: Q-02 | B4: A | C4: CFO | D4: วงเงิน DOA นับรวม VAT หรือไม่ | E4: ยอดใกล้ขอบไปผิดคน (ฉาก 5) | F4: รวม VAT | G4: OQ-02
A5: Q-03 | B5: A | C5: CEO COO | D5: ผู้มีอำนาจขอซื้อเอง ให้ยกไปผู้อนุมัติช่วงถัดไปแบบใน demo ได้ไหม | E5: ผู้ขอห้ามอนุมัติตัวเอง | F5: ยกไปช่วงถัดไป | G5: BR-DOA-06
A6: Q-04 | B6: A | C6: CEO CFO | D6: ยอดเท่าไรที่ต้องยืนยัน PIN ก่อนอนุมัติบนมือถือ | E6: ความปลอดภัยเทียบความสะดวก | F6: 100,000 บาท | G6: OQ-07
A7: Q-05 | B7: A | C7: CEO COO | D7: แต่ละขั้นควรตัดสินภายในกี่ชั่วโมงทำการ และเลยแล้วให้ส่งต่ออย่างไร | E7: การเตือนและการส่งต่ออัตโนมัติ | F7: DM VP COO 8 ชม. · CEO 16 ชม. · เตือนที่ 50% · เพิ่มผู้อนุมัติช่วงถัดไปหลังเกิน 8 ชม. | G7: OQ-14 OQ-06
A8: Q-06 | B8: A | C8: CEO ตรวจสอบภายใน | D8: ใครอนุมัติชุดตั้งต้น (ผู้ดำรงตำแหน่งและ DOA ฉบับแรก) และใครอนุมัติเมื่อเปลี่ยนตัว CEO | E8: ฝ่ายตรวจสอบภายในจะถามแน่นอน | F8: ผู้มีอำนาจลงนามตามสัญญา · ORG_ADMIN อีกคนที่ไม่ใช่ผู้เสนอ | G8: OQ-31 OQ-32 | I8: สัญญาหรือหนังสือมอบอำนาจ
A9: Q-07 | B9: A | C9: CEO CFO | D9: ใครดูแล DOA ในระบบ และมี ORG_ADMIN อย่างน้อย 2 คนได้ไหม | E9: การแยกหน้าที่ | F9: ORG_ADMIN 2 คน | G9: OQ-34
A10: Q-08 | B10: A | C10: CEO กฎหมาย | D10: เก็บข้อมูลบน cloud ภูมิภาคสิงคโปร์ได้ไหม หรือต้องอยู่ในไทย | E10: ใช้ข้อมูลจริงไม่ได้จนกว่าจะตอบ | F10: Neon สิงคโปร์ | G10: OQ-19 | I10: นโยบายข้อมูลของบริษัท
A11: Q-09 | B11: A | C11: CEO COO | D11: ตัวชี้วัดความสำเร็จของการทดลองใช้ และค่าปัจจุบัน | E11: ใช้รีวิว 60 วัน | F11: เป้าใน §1.3 | G11: P0-09 | I11: ตัวเลขปัจจุบันถ้ามี
A12: Q-10 | B12: A | C12: CEO COO CFO | D12: ยืนยันขอบเขตชั้น 1 และต้องการระบบจ่ายเงิน (ชั้น 2) เมื่อไร | E12: วางแผนงานและราคา | F12: S1–S5 ตามแผน | G12: §1.5
A13: Q-11 | B13: B | C13: จัดซื้อ | D13: ประเภทคำขอที่ใช้จริง 4–6 แบบ และฟิลด์ที่ต้องกรอกของแต่ละแบบ | E13: ฟอร์มและแคตตาล็อก | F13: 5 ประเภทใน demo | G13: IN-11 | I13: ฟอร์มขอซื้อขอจ้างปัจจุบัน
A14: Q-12 | B14: B | C14: จัดซื้อ | D14: ยอดเท่าไรต้องมีใบเสนอราคา 3 ราย และกรณีผู้ขายรายเดียวต้องมีอะไร | E14: กฎเอกสารแนบ | F14: เกิน 100,000 รวม VAT | G14: OQ-08
A15: Q-13 | B15: B | C15: จัดซื้อ | D15: รวม PR เป็น PO วันละกี่รอบ เวลาไหน | E15: รอบรวม PR | F15: 10:00 และ 15:00 | G15: OQ-13
A16: Q-14 | B16: B | C16: จัดซื้อ | D16: มีกรณีออก PO โดยไม่มี PR ไหม | E16: ประตูเดียว | F16: ไม่อนุญาต | G16: OQ-24
A17: Q-15 | B17: B | C17: จัดซื้อ | D17: การขอเพิ่มผู้ขายรายใหม่ต้องมีคนอนุมัติไหม | E17: ทะเบียนผู้ขาย | F17: เข้าคิวจัดซื้อ ไม่ผ่าน DOA | G17: OQ-23 | I17: รายชื่อผู้ขายปัจจุบัน
A18: Q-16 | B18: B | C18: จัดซื้อ IT | D18: อีเมล PO ถึงผู้ขายส่งจากโดเมนบริษัทได้ไหม ใครรับ reply | E18: ความน่าเชื่อถือของอีเมล | F18: โดเมน BCS + reply-to จัดซื้อ | G18: OQ-22
A19: Q-17 | B19: B | C19: จัดซื้อ บัญชี | D19: เอกสาร PR/PO ที่พิมพ์ต้องมีลายเซ็น หรือแค่ข้อมูลการอนุมัติ | E19: แม่แบบเอกสาร | F19: ส่วนการอนุมัติแบบข้อมูล | G19: OQ-25 | I19: แบบฟอร์ม PR/PO ที่พิมพ์อยู่
A20: Q-18 | B20: C | C20: บัญชี | D20: ปีงบเริ่มเดือนไหน และเลขเอกสารรีเซ็ตตามปีปฏิทินหรือปีงบ | E20: งบและเลขเอกสาร | F20: ม.ค.–ธ.ค. · รีเซ็ตตามปี พ.ศ. | G20: OQ-11 | I20: ไฟล์งบประมาณปีนี้
A21: Q-19 | B21: C | C21: บัญชี | D21: งบนับยอดก่อน VAT ใช่ไหม | E21: การตัดงบ | F21: ก่อน VAT | G21: OQ-03
A22: Q-20 | B22: C | C22: บัญชี | D22: ใช้งบของฝ่ายอื่นได้ไหม และให้ผู้อนุมัติของฝ่ายเจ้าของงบใช่ไหม | E22: ผู้อนุมัติข้ามฝ่าย | F22: ฝ่ายเจ้าของงบ | G22: OQ-27
A23: Q-21 | B23: C | C23: บัญชี | D23: งบที่ค้างตอนสิ้นปียกไปปีหน้าไหม | E23: การปิดปีงบ | F23: ไม่ยกอัตโนมัติ | G23: OQ-26
A24: Q-22 | B24: C | C24: บัญชี | D24: คิด VAT ระดับเอกสารหรือรายบรรทัด | E24: ยอดต่างกันได้หลักสตางค์ | F24: ระดับเอกสาร | G24: OQ-17
A25: Q-23 | B25: C | C25: บัญชี | D25: คำอ่านจำนวนเงิน 101 บาท เขียน "หนึ่งร้อยหนึ่ง" หรือ "หนึ่งร้อยเอ็ด" | E25: เอกสารพิมพ์ | F25: หนึ่งร้อยหนึ่ง | G25: OQ-28
A26: Q-24 | B26: C | C26: บัญชี จัดซื้อ | D26: รูปแบบเลขที่ PR PO GR ที่ใช้อยู่ | E26: ความต่อเนื่องของเอกสาร | F26: PR-{BE}-{SEQ5} | G26: OQ-12
A27: Q-25 | B27: C | C27: บัญชี | D27: ขอไฟล์ตัวอย่างที่ Express นำเข้าได้ และเวอร์ชันของ Express · ไฟล์นำเข้าต้องอ้างรหัสเจ้าหนี้ไหม และนำเข้าทะเบียนเจ้าหนี้เป็นไฟล์ได้ไหม | E27: ส่งต่อให้บัญชี | F27: mapping ตั้งค่าได้ · ใช้ expressVendorCode | G27: OQ-10 | I27: ไฟล์ตัวอย่าง Express และทะเบียนเจ้าหนี้
A28: Q-26 | B28: C | C28: บัญชี | D28: ยืนยันรายงาน 7 ฉบับตาม proposal และขอตัวอย่างรายงานที่ใช้จริง · ต้องการรายงานรับของแล้วยังไม่มีใบกำกับเพื่อตั้งค้างจ่ายไหม | E28: รายงาน | F28: framework + รายงานตาม proposal | G28: OQ-09 | I28: ตัวอย่างรายงาน
A29: Q-27 | B29: C | C29: บัญชี กฎหมาย | D29: ต้องเก็บเอกสารและ log นานเท่าไร | E29: PDPA และกฎหมายบัญชี | F29: 5 ปี · log 1 ปี | G29: OQ-30
A30: Q-28 | B30: D | C30: หน้างาน ผู้ตรวจรับ | D30: ผู้ขอรับของเองได้ไหม (ผู้อนุมัติห้ามรับ) | E30: การแยกหน้าที่ | F30: ได้ | G30: OQ-04 | I30: ขั้นตอนตรวจรับปัจจุบัน
A31: Q-29 | B31: D | C31: หน้างาน | D31: รับเกินจำนวนได้กี่ % | E31: variance | F31: 0% | G31: OQ-20
A32: Q-30 | B32: D | C32: หน้างาน จัดซื้อ | D32: ใครอนุมัติเมื่อรับไม่ครบ ของเสีย หรือรับเกิน | E32: variance | F32: DM ของฝ่ายเจ้าของงบ | G32: OQ-21
A33: Q-31 | B33: E | C33: การตลาด IT | D33: บริษัทมี LINE OA อยู่แล้วไหม ใครเป็นเจ้าของ แพ็กเกจอะไร | E33: ช่องทางหลัก | F33: OA ของลูกค้า | G33: OQ-15
A34: Q-32 | B34: E | C34: IT | D34: ใช้อีเมลบริษัทระบบไหน (Google Workspace หรือ Microsoft 365) จะเปิด SSO ไหม | E34: การ login | F34: อีเมล + รหัสผ่าน + TOTP | G34: FR-AUTH-004
A35: Q-33 | B35: E | C35: HR | D35: ปฏิทินวันหยุดและเวลาทำการของบริษัท | E35: การนับ SLA | F35: จ.–ศ. 08:30–17:30 | G35: OQ-14 | I35: ปฏิทินวันหยุด
A36: Q-34 | B36: E | C36: กฎหมาย DPO | D36: ผู้ติดต่อ DPO และนโยบาย PDPA ที่ต้องทำตาม | E36: PDPA | F36: ทำ ROPA ก่อนใช้ข้อมูลจริง | G36: OQ-19 OQ-30 | I36: นโยบาย PDPA
A37: Q-35 | B37: C | C37: บัญชี | D37: ผู้ขายออก e-Tax Invoice กี่ราย และแบบไหน (by Email หรือระบบเต็มรูปแบบ) | E37: อ่าน e-Tax มาเติมฟอร์ม | F37: รองรับทั้ง PDF/A-3 ที่ฝัง XML และไฟล์ XML | G37: OQ-35 | I37: ตัวอย่างไฟล์ e-Tax
A38: Q-36 | B38: B | C38: จัดซื้อ | D38: PO ไม่มีความเคลื่อนไหวกี่วันจึงเตือนให้ปิด | E38: งบที่ถูกถือไว้นานเกินจำเป็น | F38: 30 วัน | G38: OQ-36
A39: Q-37 | B39: E | C39: กฎหมาย DPO | D39: มีแม่แบบข้อตกลงการประมวลผลข้อมูล (DPA) ไหม และผู้ขายแบบไหนต้องลงนาม | E39: กฎ ATT-DPA | F39: บังคับแนบเมื่อผู้ขายประมวลผลข้อมูลส่วนบุคคล | G39: BR-FORM-05 | I39: แม่แบบ DPA
A40: B-01 | B40: BCS | C40: ทีม BCS | D40: LIFF ใช้ LINE MINI App หรือ LINE Login channel ใน production | E40: การเผยแพร่และการ login ใน LINE | F40: MINI App + ตรวจ ID token เอง | G40: OQ-16
...

Sheet Org
A1: key | B1: value | C1: labelTh | D1: ref
A2: ชื่อค่า (ห้ามแก้) | B2: ค่า | C2: ความหมาย | D2: อ้างอิง
A3: code | B3: DEMO | C3: รหัสองค์กรในระบบ | D3: §6.2
A4: legalNameTh | B4: บริษัท เดโม่ ก่อสร้าง จำกัด | C4: ชื่อจดทะเบียนภาษาไทย (สมมติ) | D4: IN-01
A5: legalNameEn | B5: Demo Construction Co., Ltd. | C5: ชื่อจดทะเบียนภาษาอังกฤษ (สมมติ) | D5: IN-01
A6: displayName | B6: DEMO | C6: ชื่อที่แสดงในแอป เปลี่ยนเป็นชื่อ LK-RICH ได้ถ้าได้รับอนุญาต | D6: IN-01
A7: taxId | B7: 0999999000055 | C7: เลขผู้เสียภาษี 13 หลัก (สังเคราะห์ ผ่าน mod-11) | D7: BR-TAXID-01
A8: branchCode | B8: 00000 | C8: สาขา (00000 = สำนักงานใหญ่) | D8: IN-01
A9: address | B9: 99 ถนนตัวอย่าง แขวงทดสอบ เขตสาธิต กรุงเทพฯ 10000 (สมมติ) | C9: ที่อยู่บนหัวเอกสาร | D9: IN-01
A10: logoFile | C10: ไฟล์โลโก้ (ว่าง = ใช้โลโก้ BCS ใน demo) | D10: IN-01
A11: timezone | B11: Asia/Bangkok | C11: เขตเวลา | D11: §5.1
A12: fiscalYearStartMonth | B12: 1 | C12: เดือนเริ่มปีงบ (1 = มกราคม) | D12: OQ-11
A13: contractSignatory | B13: ceo | C13: ผู้มีอำนาจลงนามตามสัญญา อนุมัติชุดตั้งต้น | D13: OQ-31
A14: orgAdmins | B14: admin,admin2 | C14: ORG_ADMIN อย่างน้อย 2 คน | D14: OQ-32
A15: currency | B15: THB | C15: สกุลเงิน | D15: A-02

Sheet Departments
A1: code | B1: nameTh | C1: parent | D1: kind
A2: รหัสแผนก | B2: ชื่อแผนก | C2: แผนกแม่ (ว่าง = ราก) | D2: COMPANY DIVISION DEPARTMENT SECTION
A3: HQ | B3: สำนักงานใหญ่ | D3: COMPANY
A4: OPS | B4: สายปฏิบัติการ | C4: HQ | D4: DIVISION
A5: CON | B5: ฝ่ายก่อสร้าง | C5: OPS | D5: DEPARTMENT
A6: PROC | B6: ฝ่ายจัดซื้อ | C6: OPS | D6: DEPARTMENT
A7: SUP | B7: สายสนับสนุน | C7: HQ | D7: DIVISION
A8: FIN | B8: ฝ่ายบัญชีและการเงิน | C8: SUP | D8: DEPARTMENT
A9: IT | B9: ฝ่ายไอที | C9: SUP | D9: DEPARTMENT

Sheet Positions
A1: code | B1: nameTh | C1: scope
A2: รหัสตำแหน่ง | B2: ชื่อตำแหน่ง | C2: DEPARTMENT = ผูกกับแผนก · ORG = ผูกกับแผนกราก
A3: DM | B3: ผู้จัดการฝ่าย | C3: DEPARTMENT
A4: VP | B4: รองประธานสายงาน | C4: DEPARTMENT
A5: COO | B5: ประธานเจ้าหน้าที่ฝ่ายปฏิบัติการ | C5: ORG
A6: CEO | B6: ประธานเจ้าหน้าที่บริหาร | C6: ORG
A7: PROC_MGR | B7: ผู้จัดการจัดซื้อ | C7: ORG

Sheet Users
A1: code | B1: displayNameTh | C1: email | D1: department | E1: roles | F1: positions | G1: note
A2: รหัสผู้ใช้ | B2: ชื่อที่แสดง (สมมติ) | C2: อีเมลบริษัท | D2: แผนกหลัก | E2: บทบาทคั่นด้วย , (ผู้ขอได้โดยปริยาย) | F2: ตำแหน่ง@แผนก คั่นด้วย ; | G2: หมายเหตุ
A3: req_con | B3: สมชาย ใจดี | C3: req_con@demo.bcs.local | D3: CON
A4: req_con2 | B4: วิศวะ หน้างาน | C4: req_con2@demo.bcs.local | D4: CON | G4: demo เพิ่ม: วิศวกรไซต์ B
A5: asst_con | B5: สมหญิง รักงาน | C5: asst_con@demo.bcs.local | D5: CON | G5: ผู้รักษาการในฉาก demo
A6: receiver_con | B6: ประเสริฐ ตรวจดี | C6: receiver_con@demo.bcs.local | D6: CON | E6: RECEIVER
A7: dm_con | B7: ดำรง ก่อสร้างไทย | C7: dm_con@demo.bcs.local | D7: CON | F7: DM@CON
A8: proc_officer | B8: พิมพ์ใจ จัดหา | C8: proc_officer@demo.bcs.local | D8: PROC | E8: PROCUREMENT
A9: dm_proc | B9: ปรีชา จัดซื้อ | C9: dm_proc@demo.bcs.local | D9: PROC | E9: PROCUREMENT | F9: DM@PROC;PROC_MGR@HQ
A10: fin_officer | B10: ฟ้าใส บัญชี | C10: fin_officer@demo.bcs.local | D10: FIN | E10: FINANCE,BUDGET_ADMIN
A11: dm_fin | B11: ธนา การเงิน | C11: dm_fin@demo.bcs.local | D11: FIN | E11: FINANCE | F11: DM@FIN
A12: auditor | B12: อรุณ ตรวจสอบ | C12: auditor@demo.bcs.local | D12: FIN | E12: AUDITOR
A13: req_it | B13: ไอยรา ระบบงาน | C13: req_it@demo.bcs.local | D13: IT | G13: demo เพิ่ม
A14: dm_it | B14: ไอศูรย์ ระบบดี | C14: dm_it@demo.bcs.local | D14: IT | F14: DM@IT
A15: admin | B15: แอดมิน ดูแลระบบ | C15: admin@demo.bcs.local | D15: IT | E15: ORG_ADMIN
A16: admin2 | B16: สมศักดิ์ ดูแลร่วม | C16: admin2@demo.bcs.local | D16: FIN | E16: ORG_ADMIN
A17: vp_ops | B17: วีระ ปฏิบัติการ | C17: vp_ops@demo.bcs.local | D17: OPS | F17: VP@OPS
A18: vp_sup | B18: วิไล สนับสนุน | C18: vp_sup@demo.bcs.local | D18: SUP | F18: VP@SUP
A19: coo | B19: ชัยวัฒน์ ปฏิบัติการใหญ่ | C19: coo@demo.bcs.local | D19: HQ | E19: EXECUTIVE | F19: COO@HQ
A20: ceo | B20: ศักดิ์ชัย ผู้นำ | C20: ceo@demo.bcs.local | D20: HQ | E20: EXECUTIVE | F20: CEO@HQ

Sheet DOA
A1: version | B1: ruleCode | C1: documentType | D1: gt | E1: lte | F1: approverKind | G1: approverPosition | H1: approverMember | I1: slaBusinessHours | J1: descriptionTh
A2: ฉบับ | B2: รหัสข้อ | C2: ประเภทเอกสาร | D2: มากกว่า (บาท) ว่าง = ไม่มีขอบล่าง | E2: ไม่เกิน (บาท) ว่าง = ไม่มีขอบบน | F2: วิธีหาผู้อนุมัติ | G2: ตำแหน่ง | H2: ผู้ใช้ (ถ้าระบุตัว) | I2: SLA ชั่วโมงทำการ | J2: คำอธิบาย
A3: 1 | B3: PR-01 | C3: PURCHASE_REQUEST | D3: 0 | E3: 20000 | F3: POSITION_OF_DEPARTMENT | G3: DM | I3: 8 | J3: ขอซื้อไม่เกิน 20,000 บาท → ผู้จัดการฝ่าย
A4: 1 | B4: PR-02 | C4: PURCHASE_REQUEST | D4: 20000 | E4: 100000 | F4: POSITION_OF_DEPARTMENT | G4: VP | I4: 8 | J4: ขอซื้อเกิน 20,000 ถึง 100,000 บาท → VP ของสายงาน
A5: 1 | B5: PR-03 | C5: PURCHASE_REQUEST | D5: 100000 | F5: POSITION_OF_ORG | G5: CEO | I5: 16 | J5: ขอซื้อเกิน 100,000 บาท → CEO
A6: 1 | B6: PO-01 | C6: PURCHASE_ORDER | D6: 0 | E6: 1000000 | F6: POSITION_OF_ORG | G6: COO | I6: 8 | J6: สั่งซื้อไม่เกิน 1,000,000 บาท → COO
A7: 1 | B7: PO-02 | C7: PURCHASE_ORDER | D7: 1000000 | F7: POSITION_OF_ORG | G7: CEO | I7: 16 | J7: สั่งซื้อเกิน 1,000,000 บาท → CEO
A8: 1 | B8: GRV-01 | C8: GR_VARIANCE | F8: POSITION_OF_DEPARTMENT | G8: DM | I8: 8 | J8: variance ตรวจรับ → ผู้จัดการฝ่ายเจ้าของงบ (OQ-21)
A9: 1 | B9: DOA-CHG-01 | C9: DOA_CHANGE | F9: POSITION_OF_ORG | G9: CEO | I9: 16 | J9: แก้ DOA → CEO (4 ตา + PIN)
A10: 1 | B10: ORG-CHG-01 | C10: ORG_AUTHORITY_CHANGE | F10: POSITION_OF_ORG | G10: CEO | I10: 16 | J10: เปลี่ยนผู้ดำรงตำแหน่ง ย้ายแผนก รักษาการแทน → CEO

Sheet DOA_Policy
A1: key | B1: value | C1: labelTh | D1: ref
A2: ชื่อค่า (ห้ามแก้) | B2: ค่า | C2: ความหมาย | D2: อ้างอิง
A3: code | B3: DOA-DEMO | C3: รหัสชุด DOA | D3: §7.4
A4: version | B4: 1 | C4: ฉบับที่ใช้ใน demo | D4: §7.4
A5: effectiveFrom | B5: 46023 | C5: วันมีผล (demo ใช้ต้นปีให้คำขอย้อนหลังอยู่ในฉบับนี้) | D5: BR-DOA-01
A6: amountBasis | B6: GROSS | C6: วงเงินนับรวม VAT | D6: OQ-02
A7: selfApprovalPolicy | B7: ESCALATE_NEXT_BAND | C7: ผู้อนุมัติขอเอง → ยกไปช่วงถัดไป | D7: BR-DOA-06
A8: collapseDuplicateApprovers | B8: Y | C8: รวมขั้นที่ผู้อนุมัติซ้ำ | D8: OQ-05
A9: stepUpThreshold | B9: 100000 | C9: ยอดที่ต้องยืนยัน PIN | D9: OQ-07
A10: approverMayReceive | B10: N | C10: ผู้อนุมัติตรวจรับของเองได้ไหม | D10: BR-SOD-02
A11: requesterMayReceive | B11: Y | C11: ผู้ขอตรวจรับของเองได้ไหม | D11: OQ-04
A12: remindPct | B12: 0.5 | C12: เตือนเมื่อผ่าน % ของ SLA | D12: OQ-06
A13: escalateAfterBusinessHours | B13: 8 | C13: เกินกำหนดแล้วกี่ชั่วโมงจึงเพิ่มผู้อนุมัติช่วงถัดไป | D13: OQ-06

Sheet Budget
A1: fiscalYear | B1: code | C1: nameTh | D1: department | E1: costCenter | F1: accountCode | G1: planned | H1: usedDemo | I1: remaining | J1: remainingPct | K1: note
A2: ปีงบ | B2: รหัสบรรทัดงบ | C2: ชื่อ | D2: แผนกเจ้าของงบ | E2: cost center | F2: รหัสบัญชี | G2: งบตั้งต้น (บาท ก่อน VAT) | H2: ใช้แล้วจากคำขอย้อนหลัง (สูตร) | I2: คงเหลือ (สูตร) | J2: % คงเหลือ (สูตร) | K2: หมายเหตุ
A3: FY2569 | B3: CON-OPEX-2569 | C3: ค่าใช้จ่ายดำเนินงาน ฝ่ายก่อสร้าง | D3: CON | E3: CC-CON | F3: 5101 (สมมติ) | G3: 500000 | H3: =SUMIFS(Demo_History!$N:$N,Demo_History!$I:$I,B3) -> 239000 | I3: =G3-H3 -> 261000 | J3: =IF(G3=0,0,I3/G3) -> 0.522
A4: FY2569 | B4: CON-CAPEX-2569 | C4: ลงทุนเครื่องมือและอุปกรณ์ ฝ่ายก่อสร้าง | D4: CON | E4: CC-CON | F4: 1201 (สมมติ) | G4: 2000000 | H4: =SUMIFS(Demo_History!$N:$N,Demo_History!$I:$I,B4) -> 620000 | I4: =G4-H4 -> 1380000 | J4: =IF(G4=0,0,I4/G4) -> 0.69
A5: FY2569 | B5: PROC-OPEX-2569 | C5: ค่าใช้จ่ายดำเนินงาน ฝ่ายจัดซื้อ | D5: PROC | E5: CC-PROC | F5: 5102 (สมมติ) | G5: 50000 | H5: =SUMIFS(Demo_History!$N:$N,Demo_History!$I:$I,B5) -> 3000 | I5: =G5-H5 -> 47000 | J5: =IF(G5=0,0,I5/G5) -> 0.94
A6: FY2569 | B6: FIN-OPEX-2569 | C6: ค่าใช้จ่ายดำเนินงาน ฝ่ายบัญชีและการเงิน | D6: FIN | E6: CC-FIN | F6: 5103 (สมมติ) | G6: 100000 | H6: =SUMIFS(Demo_History!$N:$N,Demo_History!$I:$I,B6) -> 49500 | I6: =G6-H6 -> 50500 | J6: =IF(G6=0,0,I6/G6) -> 0.505
A7: FY2569 | B7: IT-OPEX-2569 | C7: ค่าใช้จ่ายดำเนินงาน ฝ่ายไอที | D7: IT | E7: CC-IT | F7: 5104 (สมมติ) | G7: 300000 | H7: =SUMIFS(Demo_History!$N:$N,Demo_History!$I:$I,B7) -> 275000 | I7: =G7-H7 -> 25000 | J7: =IF(G7=0,0,I7/G7) -> 0.083333333 | K7: เหลือต่ำกว่า 10% → ขึ้นในสรุปรายวัน (ใช้ในฉาก demo)
C9: รวม | G9: =SUM(G3:G7) -> 2950000 | H9: =SUM(H3:H7) -> 1186500 | I9: =SUM(I3:I7) -> 1763500 | J9: =IF(G9=0,0,I9/G9) -> 0.59779661

Sheet Suppliers
A1: code | B1: nameTh | C1: taxId | D1: branchCode | E1: vatRegistered | F1: email | G1: phone | H1: category | I1: expressVendorCode
A2: รหัส | B2: ชื่อผู้ขาย (สมมติ) | C2: เลขผู้เสียภาษี (ข้อความ 13 หลัก) | D2: สาขา | E2: จด VAT (Y/N) | F2: อีเมลรับ PO | G2: โทร | H2: หมวด | I2: รหัสเจ้าหนี้ใน Express (ถ้าไฟล์นำเข้าต้องใช้ · OQ-10)
A3: S1 | B3: บริษัท วัสดุก่อสร้างทดสอบ จำกัด | C3: 0999999000012 | D3: 00000 | E3: Y | F3: s1@supplier.demo.local | G3: 02-000-0001 | H3: วัสดุก่อสร้าง เช่าเครื่องมือ | I3: V0001
A4: S2 | B4: บริษัท ไอทีทดสอบ จำกัด | C4: 0999999000021 | D4: 00000 | E4: Y | F4: s2@supplier.demo.local | G4: 02-000-0002 | H4: ไอที | I4: V0002
A5: S3 | B5: บริษัท บริการทำความสะอาดทดสอบ จำกัด | C5: 0999999000039 | D5: 00000 | E5: Y | F5: s3@supplier.demo.local | G5: 02-000-0003 | H5: บริการทั่วไป วัสดุสำนักงาน | I5: V0003
A6: S4 | B6: ห้างหุ้นส่วนจำกัด รับเหมาเล็กทดสอบ | C6: 0999999000047 | D6: 00000 | E6: N | F6: s4@supplier.demo.local | G6: 02-000-0004 | H6: รับเหมาย่อย | I6: V0004
A7: S5 | B7: สำนักงานบัญชีทดสอบ จำกัด | C7: 0999999000063 | D7: 00000 | E7: Y | F7: s5@supplier.demo.local | G7: 02-000-0005 | H7: บริการวิชาชีพ | I7: V0005

Sheet Sites
A1: code | B1: nameTh | C1: address
A2: รหัส | B2: ชื่อสถานที่ส่ง | C2: ที่อยู่ (สมมติ)
A3: SITE-A | B3: ไซต์งานตัวอย่าง A | C3: ไซต์ก่อสร้างสมมติ A
A4: SITE-B | B4: ไซต์งานตัวอย่าง B | C4: ไซต์ก่อสร้างสมมติ B
A5: HQ-STORE | B5: คลังสำนักงานใหญ่ | C5: สำนักงานใหญ่ (สมมติ)

Sheet RequestTypes
A1: code | B1: nameTh | C1: documentType | D1: descriptionTh | E1: keyFields | F1: attachmentRule | G1: active
A2: รหัส | B2: ชื่อบนการ์ด | C2: ชนิดเอกสาร | D2: ใช้เมื่อไร | E2: ฟิลด์สำคัญ | F2: กฎเอกสารแนบ | G2: ใช้งาน (Y/N)
A3: BUY_GOODS | B3: ซื้อของ | C3: PURCHASE_REQUEST | D3: วัสดุ อุปกรณ์ สินค้าทั่วไป | E3: รายการ จำนวน หน่วย ราคาประมาณ สถานที่ส่ง วันที่ต้องใช้ บรรทัดงบ | F3: ATT-QUOTES | G3: Y
A4: HIRE_SERVICE | B4: จ้างบริการ | C4: PURCHASE_REQUEST | D4: บริการรายครั้งหรือรายเดือน เช่าเครื่องมือ | E4: ขอบเขตงาน ระยะเวลา วันสิ้นสุดบริการ ราคาประมาณ ใบเสนอราคา บรรทัดงบ · คำถามคัดกรอง 3 ข้อ (ข้อมูลส่วนบุคคล ระบบ พื้นที่) | F4: ATT-QUOTES · ATT-DPA | G4: Y
A5: CONTRACT_WORK | B5: จ้างเหมา | C5: PURCHASE_REQUEST | D5: งานเหมาที่มีงวดงาน | E5: ขอบเขตงาน งวดงาน ไซต์ ราคาประมาณ บรรทัดงบ | F5: ATT-QUOTES | G5: Y
A6: IT_PURCHASE | B6: ซื้ออุปกรณ์/ซอฟต์แวร์ไอที | C6: PURCHASE_REQUEST | D6: ฮาร์ดแวร์ ซอฟต์แวร์ ไลเซนส์ | E6: หมวด (HARDWARE/SOFTWARE) รายการ จำนวน ราคาประมาณ assetTag เมื่อเป็นฮาร์ดแวร์ วันสิ้นสุดไลเซนส์ · คำถามคัดกรอง 3 ข้อ (ข้อมูลส่วนบุคคล ระบบ พื้นที่) | F6: ATT-QUOTES · ATT-DPA | G6: Y
A7: NEW_SUPPLIER | B7: ขอเพิ่มผู้ขายรายใหม่ | C7: SUPPLIER_REQUEST | D7: ผู้ขายที่ยังไม่อยู่ในทะเบียน | E7: ชื่อ เลขผู้เสียภาษี สาขา อีเมล เหตุผล | F7: — | G7: Y

Sheet Holidays
A1: date | B1: nameTh | C1: source
A2: วันที่ | B2: ชื่อวันหยุด | C2: ที่มา
A3: 46308 | B3: วันนวมินทรมหาราช | C3: ตัวอย่าง · ใช้ในเทสต์ SLA
A4: 46318 | B4: วันปิยมหาราช | C4: ตัวอย่าง · ใช้ในเทสต์ SLA
A5: 46363 | B5: ชดเชยวันพ่อแห่งชาติ | C5: ตัวอย่าง
A6: 46366 | B6: วันรัฐธรรมนูญ | C6: ตัวอย่าง
A7: 46387 | B7: วันสิ้นปี | C7: ตัวอย่าง
A8: 46388 | B8: วันขึ้นปีใหม่ | C8: ตัวอย่าง

Sheet Settings
A1: key | B1: value | C1: labelTh | D1: ref
A2: ชื่อค่า (ห้ามแก้) | B2: ค่าที่ใช้ | C2: ความหมาย | D2: อ้างอิงใน spec
A3: vatRate | B3: 0.07 | C3: อัตรา VAT ที่ใช้คำนวณใน demo (ระบบจริงอ่านจากตาราง TaxRate ตามวันที่) | D3: §7.1 OQ-29
A4: budgetBasis | B4: NET | C4: งบนับยอดก่อน VAT | D4: OQ-03
A5: workdays | B5: MON,TUE,WED,THU,FRI | C5: วันทำงาน | D5: OQ-14
A6: businessHoursStart | B6: 08:30 | C6: เริ่มเวลาทำการ | D6: OQ-14
A7: businessHoursEnd | B7: 17:30 | C7: เลิกเวลาทำการ (ไม่หักพักเที่ยง) | D7: A-07
A8: numbering.PR | B8: PR-{BE}-{SEQ5} | C8: รูปแบบเลขใบขอซื้อ | D8: OQ-12
A9: numbering.PO | B9: PO-{BE}-{SEQ5} | C9: รูปแบบเลขใบสั่งซื้อ | D9: OQ-12
A10: numbering.GR | B10: GR-{BE}-{SEQ5} | C10: รูปแบบเลขใบตรวจรับ | D10: OQ-12
A11: numbering.RQ | B11: RQ-{BE}-{SEQ5} | C11: รูปแบบเลขคำขอผู้ขายรายใหม่ | D11: OQ-12
A12: numbering.reset | B12: YEARLY | C12: รีเซ็ตเลขทุกปี พ.ศ. | D12: OQ-11
A13: consolidation.cron | B13: TZ=Asia/Bangkok 0 10,15 * * 1-5 | C13: รอบรวม PR เป็น PO | D13: OQ-13
A14: quoteThresholdGross | B14: 100000 | C14: ยอดรวม VAT ที่เกินแล้วต้องมีใบเสนอราคา 3 ราย | D14: OQ-08
A15: receiving.overTolerancePct | B15: 0 | C15: รับเกินได้กี่ % | D15: OQ-20
A16: priceAlertPct | B16: 0.1 | C16: เตือนเมื่อราคาใหม่แพงกว่าครั้งก่อนเกินเท่านี้ | D16: FR-P2P-003
A17: digest.budgetLowPct | B17: 0.1 | C17: สรุปรายวันแจ้งบรรทัดงบที่เหลือต่ำกว่านี้ | D17: FR-LINE-006
A18: vatRounding | B18: DOCUMENT | C18: คิด VAT ระดับเอกสาร | D18: OQ-17
A19: bahtTextStyle | B19: LIBREOFFICE | C19: 101 = หนึ่งร้อยหนึ่ง | D19: OQ-28
A20: poWithoutPr | B20: N | C20: ออก PO โดยไม่มี PR ได้ไหม | D20: OQ-24
A21: newSupplierRequiresDoa | B21: N | C21: คำขอผู้ขายใหม่ต้องผ่าน DOA ไหม | D21: OQ-23
A22: printSignatureMode | B22: APPROVAL_BLOCK | C22: เอกสารพิมพ์แสดงข้อมูลการอนุมัติแทนลายเซ็น | D22: OQ-25
A23: budgetCarryOver | B23: N | C23: ยกงบข้ามปีอัตโนมัติไหม | D23: OQ-26
A24: crossBudgetApproverDept | B24: CHARGED | C24: ใช้งบข้ามฝ่ายให้ผู้อนุมัติของฝ่ายเจ้าของงบ | D24: OQ-27
A25: email.fromAddress | B25: no-reply@bcs.local | C25: ผู้ส่งอีเมล PO ใน demo | D25: OQ-22
A26: retention.documentYears | B26: 5 | C26: เก็บเอกสารกี่ปี | D26: OQ-30
A27: line.channelOwner | B27: BCS_DEMO | C27: demo ใช้ LINE OA และ channel ของ BCS · v2 ค่าเริ่มต้นคือ OA ของลูกค้า | D27: OQ-15 OQ-16
A28: express.encoding | B28: UTF-8-BOM | C28: encoding ไฟล์ส่ง Express (รอไฟล์ตัวอย่าง) | D28: OQ-10
A29: poIdleDays | B29: 30 | C29: PO ไม่มีความเคลื่อนไหวกี่วันจึงเตือนให้ปิด | D29: OQ-36
A30: registry.mode | B30: stub | C30: ตรวจผู้ขายกับสรรพากรและ DBD: stub = ข้อมูลจำลอง · live = บริการจริง | D30: OQ-37

Sheet Demo_History
A1: ref | B1: daysAgo | C1: requester | D1: chargedDept | E1: requestType | F1: title | G1: site | H1: supplier | I1: budgetLine | J1: net | K1: vat | L1: gross | M1: status | N1: countsAgainstBudget | O1: expectedRule | P1: expectedApprover | Q1: escalated | R1: hours | S1: channel | T1: note
A2: รหัส | B2: กี่วันก่อนวัน seed | C2: ผู้ขอ | D2: แผนกเจ้าของงบ | E2: ประเภท | F2: เรื่อง | G2: สถานที่ส่ง | H2: ผู้ขาย | I2: บรรทัดงบ | J2: ยอดก่อน VAT | K2: VAT (สูตร) | L2: รวม VAT (สูตร) | M2: สถานะ | N2: นับเข้างบ (สูตร) | O2: ข้อ DOA ที่คาด | P2: ผู้อนุมัติที่คาด | Q2: ยกระดับ (Y/N) | R2: ชั่วโมงทำการที่ใช้ตัดสิน หรือที่รอแล้ว | S2: ช่องทางที่ตัดสิน | T2: หมายเหตุ
A3: H01 | B3: 40 | C3: req_it | D3: IT | E3: IT_PURCHASE | F3: โน้ตบุ๊กวิศวกรสนาม 4 เครื่อง | G3: HQ-STORE | H3: S2 | I3: IT-OPEX-2569 | J3: 120000 | K3: =ROUND(J3*Settings!$B$3,2) -> 8400 | L3: =J3+K3 -> 128400 | M3: COMPLETED | N3: =IF(OR(M3="REJECTED",M3="CANCELLED"),0,J3) -> 120000 | O3: PR-03 | P3: ceo | Q3: N | R3: 5 | S3: LIFF | T3: ยอดเกิน 100,000 แนบใบเสนอราคา 3 ราย · อนุมัติด้วย PIN
A4: H02 | B4: 33 | C4: req_it | D4: IT | E4: IT_PURCHASE | F4: ไลเซนส์ซอฟต์แวร์ออกแบบ 1 ปี | G4: HQ-STORE | H4: S2 | I4: IT-OPEX-2569 | J4: 85000 | K4: =ROUND(J4*Settings!$B$3,2) -> 5950 | L4: =J4+K4 -> 90950 | M4: ORDERED | N4: =IF(OR(M4="REJECTED",M4="CANCELLED"),0,J4) -> 85000 | O4: PR-02 | P4: vp_sup | Q4: N | R4: 3 | S4: LINE_CHAT
A5: H03 | B5: 12 | C5: req_it | D5: IT | E5: IT_PURCHASE | F5: อุปกรณ์เครือข่ายไซต์งาน | G5: SITE-B | H5: S2 | I5: IT-OPEX-2569 | J5: 45000 | K5: =ROUND(J5*Settings!$B$3,2) -> 3150 | L5: =J5+K5 -> 48150 | M5: APPROVED | N5: =IF(OR(M5="REJECTED",M5="CANCELLED"),0,J5) -> 45000 | O5: PR-02 | P5: vp_sup | Q5: N | R5: 2 | S5: LINE_CHAT | T5: รอจัดซื้อรวม PR
A6: H04 | B6: 28 | C6: dm_it | D6: IT | E6: IT_PURCHASE | F6: จอภาพห้องประชุม | G6: HQ-STORE | H6: S2 | I6: IT-OPEX-2569 | J6: 18000 | K6: =ROUND(J6*Settings!$B$3,2) -> 1260 | L6: =J6+K6 -> 19260 | M6: COMPLETED | N6: =IF(OR(M6="REJECTED",M6="CANCELLED"),0,J6) -> 18000 | O6: PR-01 | P6: vp_sup | Q6: Y | R6: 4 | S6: WEB | T6: DM ขอเอง จึงยกไป VP
A7: H05 | B7: 21 | C7: req_it | D7: IT | E7: BUY_GOODS | F7: เมาส์และคีย์บอร์ด | G7: HQ-STORE | H7: S2 | I7: IT-OPEX-2569 | J7: 7000 | K7: =ROUND(J7*Settings!$B$3,2) -> 490 | L7: =J7+K7 -> 7490 | M7: COMPLETED | N7: =IF(OR(M7="REJECTED",M7="CANCELLED"),0,J7) -> 7000 | O7: PR-01 | P7: dm_it | Q7: N | R7: 1 | S7: LINE_CHAT
A8: H06 | B8: 9 | C8: req_it | D8: IT | E8: BUY_GOODS | F8: ชุดหูฟังประชุม | G8: HQ-STORE | H8: S2 | I8: IT-OPEX-2569 | J8: 9500 | K8: =ROUND(J8*Settings!$B$3,2) -> 665 | L8: =J8+K8 -> 10165 | M8: REJECTED | N8: =IF(OR(M8="REJECTED",M8="CANCELLED"),0,J8) -> 0 | O8: PR-01 | P8: dm_it | Q8: N | R8: 2 | S8: LIFF | T8: ไม่อนุมัติ: ใช้ของเดิมได้ · งบคืนแล้ว
A9: H07 | B9: 44 | C9: req_con | D9: CON | E9: BUY_GOODS | F9: ปูนซีเมนต์ 200 ถุง | G9: SITE-A | H9: S1 | I9: CON-OPEX-2569 | J9: 28000 | K9: =ROUND(J9*Settings!$B$3,2) -> 1960 | L9: =J9+K9 -> 29960 | M9: COMPLETED | N9: =IF(OR(M9="REJECTED",M9="CANCELLED"),0,J9) -> 28000 | O9: PR-02 | P9: vp_ops | Q9: N | R9: 3 | S9: LINE_CHAT
A10: H08 | B10: 38 | C10: req_con | D10: CON | E10: BUY_GOODS | F10: เหล็กเส้น DB12 | G10: SITE-A | H10: S1 | I10: CON-OPEX-2569 | J10: 96000 | K10: =ROUND(J10*Settings!$B$3,2) -> 6720 | L10: =J10+K10 -> 102720 | M10: COMPLETED | N10: =IF(OR(M10="REJECTED",M10="CANCELLED"),0,J10) -> 96000 | O10: PR-03 | P10: ceo | Q10: N | R10: 6 | S10: LIFF | T10: ยอดรวม VAT 102,720 เกิน 100,000 → CEO และใบเสนอราคา 3 ราย
A11: H09 | B11: 30 | C11: req_con2 | D11: CON | E11: BUY_GOODS | F11: ทรายและหิน | G11: SITE-B | H11: S1 | I11: CON-OPEX-2569 | J11: 14500 | K11: =ROUND(J11*Settings!$B$3,2) -> 1015 | L11: =J11+K11 -> 15515 | M11: COMPLETED | N11: =IF(OR(M11="REJECTED",M11="CANCELLED"),0,J11) -> 14500 | O11: PR-01 | P11: dm_con | Q11: N | R11: 1 | S11: LINE_CHAT
A12: H10 | B12: 18 | C12: req_con2 | D12: CON | E12: HIRE_SERVICE | F12: ค่าเช่าเครื่องตัดคอนกรีต 1 เดือน | G12: SITE-B | H12: S1 | I12: CON-OPEX-2569 | J12: 18000 | K12: =ROUND(J12*Settings!$B$3,2) -> 1260 | L12: =J12+K12 -> 19260 | M12: ORDERED | N12: =IF(OR(M12="REJECTED",M12="CANCELLED"),0,J12) -> 18000 | O12: PR-01 | P12: dm_con | Q12: N | R12: 2 | S12: WEB
A13: H11 | B13: 8 | C13: asst_con | D13: CON | E13: BUY_GOODS | F13: อุปกรณ์ความปลอดภัย PPE | G13: SITE-A | H13: S1 | I13: CON-OPEX-2569 | J13: 12000 | K13: =ROUND(J13*Settings!$B$3,2) -> 840 | L13: =J13+K13 -> 12840 | M13: APPROVED | N13: =IF(OR(M13="REJECTED",M13="CANCELLED"),0,J13) -> 12000 | O13: PR-01 | P13: dm_con | Q13: N | R13: 1 | S13: LINE_CHAT | T13: รอจัดซื้อรวม PR (จะรวมกับฉาก 1)
A14: H12 | B14: 4 | C14: req_con | D14: CON | E14: BUY_GOODS | F14: ไม้แบบหล่อคอนกรีต | G14: SITE-A | H14: S1 | I14: CON-OPEX-2569 | J14: 38500 | K14: =ROUND(J14*Settings!$B$3,2) -> 2695 | L14: =J14+K14 -> 41195 | M14: PENDING_APPROVAL | N14: =IF(OR(M14="REJECTED",M14="CANCELLED"),0,J14) -> 38500 | O14: PR-02 | P14: vp_ops | Q14: N | R14: 18 | T14: ค้างที่ VP 18 ชม. เกิน SLA 8 ชม. → ขึ้นกระดานค้าง
A15: H13 | B15: 1 | C15: req_con2 | D15: CON | E15: BUY_GOODS | F15: สีกันสนิม | G15: SITE-B | H15: S1 | I15: CON-OPEX-2569 | J15: 6800 | K15: =ROUND(J15*Settings!$B$3,2) -> 476 | L15: =J15+K15 -> 7276 | M15: PENDING_APPROVAL | N15: =IF(OR(M15="REJECTED",M15="CANCELLED"),0,J15) -> 6800 | O15: PR-01 | P15: dm_con | Q15: N | R15: 2 | T15: ยังไม่เกิน SLA
A16: H14 | B16: 25 | C16: dm_con | D16: CON | E16: BUY_GOODS | F16: เครื่องวัดระดับเลเซอร์ | G16: SITE-A | H16: S1 | I16: CON-OPEX-2569 | J16: 16000 | K16: =ROUND(J16*Settings!$B$3,2) -> 1120 | L16: =J16+K16 -> 17120 | M16: COMPLETED | N16: =IF(OR(M16="REJECTED",M16="CANCELLED"),0,J16) -> 16000 | O16: PR-01 | P16: vp_ops | Q16: Y | R16: 2 | S16: LINE_CHAT | T16: DM ขอเอง จึงยกไป VP
A17: H15 | B17: 6 | C17: req_con | D17: CON | E17: BUY_GOODS | F17: น้ำมันเครื่องจักร | G17: SITE-A | H17: S1 | I17: CON-OPEX-2569 | J17: 9200 | K17: =ROUND(J17*Settings!$B$3,2) -> 644 | L17: =J17+K17 -> 9844 | M17: RETURNED | N17: =IF(OR(M17="REJECTED",M17="CANCELLED"),0,J17) -> 9200 | O17: PR-01 | P17: dm_con | Q17: N | R17: 3 | S17: WEB | T17: ตีกลับให้แนบใบเสนอราคา · งบยังจองไว้
A18: H16 | B18: 35 | C18: req_con | D18: CON | E18: BUY_GOODS | F18: เครื่องผสมคอนกรีต | G18: SITE-A | H18: S1 | I18: CON-CAPEX-2569 | J18: 380000 | K18: =ROUND(J18*Settings!$B$3,2) -> 26600 | L18: =J18+K18 -> 406600 | M18: ORDERED | N18: =IF(OR(M18="REJECTED",M18="CANCELLED"),0,J18) -> 380000 | O18: PR-03 | P18: ceo | Q18: N | R18: 7 | S18: LIFF | T18: PO 406,600 บาท อนุมัติโดย COO (PO-01)
A19: H17 | B19: 3 | C19: req_con2 | D19: CON | E19: BUY_GOODS | F19: นั่งร้านเหล็ก 200 ชุด | G19: SITE-B | H19: S1 | I19: CON-CAPEX-2569 | J19: 240000 | K19: =ROUND(J19*Settings!$B$3,2) -> 16800 | L19: =J19+K19 -> 256800 | M19: PENDING_APPROVAL | N19: =IF(OR(M19="REJECTED",M19="CANCELLED"),0,J19) -> 240000 | O19: PR-03 | P19: ceo | Q19: N | R19: 6 | T19: รอ CEO ยังไม่เกิน SLA 16 ชม.
A20: H18 | B20: 27 | C20: fin_officer | D20: FIN | E20: BUY_GOODS | F20: กระดาษและหมึกพิมพ์ | G20: HQ-STORE | H20: S3 | I20: FIN-OPEX-2569 | J20: 4500 | K20: =ROUND(J20*Settings!$B$3,2) -> 315 | L20: =J20+K20 -> 4815 | M20: COMPLETED | N20: =IF(OR(M20="REJECTED",M20="CANCELLED"),0,J20) -> 4500 | O20: PR-01 | P20: dm_fin | Q20: N | R20: 1 | S20: LINE_CHAT
A21: H19 | B21: 20 | C21: fin_officer | D21: FIN | E21: HIRE_SERVICE | F21: ค่าตรวจสอบบัญชีระหว่างกาล | G21: HQ-STORE | H21: S5 | I21: FIN-OPEX-2569 | J21: 45000 | K21: =ROUND(J21*Settings!$B$3,2) -> 3150 | L21: =J21+K21 -> 48150 | M21: ORDERED | N21: =IF(OR(M21="REJECTED",M21="CANCELLED"),0,J21) -> 45000 | O21: PR-02 | P21: vp_sup | Q21: N | R21: 4 | S21: WEB
A22: H20 | B22: 15 | C22: proc_officer | D22: PROC | E22: HIRE_SERVICE | F22: ค่าส่งเอกสารด่วนรายเดือน | G22: HQ-STORE | H22: S3 | I22: PROC-OPEX-2569 | J22: 3000 | K22: =ROUND(J22*Settings!$B$3,2) -> 210 | L22: =J22+K22 -> 3210 | M22: COMPLETED | N22: =IF(OR(M22="REJECTED",M22="CANCELLED"),0,J22) -> 3000 | O22: PR-01 | P22: dm_proc | Q22: N | R22: 1 | S22: LINE_CHAT

Sheet Demo_Script
A1: scene | B1: core | C1: titleTh | D1: actor | E1: channel | F1: requestType | G1: chargedDept | H1: budgetLine | I1: site | J1: net | K1: vat | L1: gross | M1: expectedOutcome | N1: expectedRule | O1: expectedApprover | P1: escalated | Q1: delegation | R1: stepsTh | S1: talkingPointTh | T1: askQuestion | U1: minutes
A2: ฉาก | B2: ต้องมี (Y) หรือเสริม (N) | C2: ชื่อฉาก | D2: ผู้ใช้ที่เล่น | E2: ช่องทาง | F2: ประเภท | G2: แผนก | H2: บรรทัดงบ | I2: สถานที่ส่ง | J2: ยอดก่อน VAT | K2: VAT (สูตร) | L2: รวม VAT (สูตร) | M2: ผลที่คาด ROUTED BLOCKED NA | N2: ข้อ DOA | O2: ผู้รับงานที่คาด | P2: ยกระดับ | Q2: รักษาการ ผู้มอบ>ผู้รักษาการ | R2: ขั้นตอน | S2: ประเด็นที่พูด | T2: คำถามที่ถามต่อ | U2: นาที
A3: 1 | B3: Y | C3: ขอซื้อจาก LINE ในหนึ่งนาที | D3: req_con | E3: LIFF | F3: BUY_GOODS | G3: CON | H3: CON-OPEX-2569 | I3: SITE-A | J3: 42000 | K3: =IF(J3="","",ROUND(J3*Settings!$B$3,2)) -> 2940 | L3: =IF(J3="","",J3+K3) -> 44940 | M3: ROUTED | N3: PR-02 | O3: vp_ops | P3: N | R3: rich menu "ขอซื้อ" → ไม้อัดและตะปู → ระบบเติมแผนก งบ และไซต์ให้ → เห็นงบคงเหลือและเส้นทาง "VP สายปฏิบัติการ (PR-02)" ก่อนกดส่ง | S3: ฟอร์มถามน้อย และบอกล่วงหน้าว่าเอกสารจะไปหาใคร | T3: Q-11 | U3: 3
A4: 2 | B4: Y | C4: อนุมัติในแชท | D4: vp_ops | E4: LINE_CHAT | K4: =IF(J4="","",ROUND(J4*Settings!$B$3,2)) | L4: =IF(J4="","",J4+K4) | M4: NA | R4: การ์ดอนุมัติเด้งในแชท → กด "อนุมัติ" → ได้การ์ดยืนยัน → เปิดหน้า audit เห็นช่องทาง LINE_CHAT และ "DOA-DEMO ฉบับ 1 ข้อ PR-02" | S4: ผู้บริหารอนุมัติได้โดยไม่ต้องเปิดคอม และทุกการอนุมัติอ้าง DOA | T4: Q-05 | U4: 2
A5: 3 | B5: Y | C5: ยอดสูงต้องยืนยัน PIN | D5: req_con2 | E5: LIFF | F5: BUY_GOODS | G5: CON | H5: CON-CAPEX-2569 | I5: SITE-B | J5: 140000 | K5: =IF(J5="","",ROUND(J5*Settings!$B$3,2)) -> 9800 | L5: =IF(J5="","",J5+K5) -> 149800 | M5: ROUTED | N5: PR-03 | O5: ceo | P5: N | R5: ขอซื้อปั๊มน้ำบาดาล → ไป CEO → CEO กดอนุมัติในแชท → ระบบเปิด LIFF ให้ใส่ PIN | S5: ยอดสูงปลอดภัยกว่าการกดปุ่มเดียว | T5: Q-04 | U5: 3
A6: 4 | B6: Y | C6: งบไม่พอ ไม่ถึงผู้อนุมัติ | D6: req_it | E6: LIFF | F6: IT_PURCHASE | G6: IT | H6: IT-OPEX-2569 | I6: HQ-STORE | J6: 60000 | K6: =IF(J6="","",ROUND(J6*Settings!$B$3,2)) -> 4200 | L6: =IF(J6="","",J6+K6) -> 64200 | M6: BLOCKED | R6: ขอซื้อเซิร์ฟเวอร์สำรองข้อมูล 60,000 บาท → ระบบบอกงบคงเหลือ 25,000 ขาด 35,000 และส่งไม่ได้ | S6: ไม่มีคำขอเกินงบหลุดไปถึงผู้บริหาร | T6: Q-19 | U6: 2
A7: 5 | B7: Y | C7: ยอดก่อน VAT กับรวม VAT | D7: req_con2 | E7: WEB | F7: BUY_GOODS | G7: CON | H7: CON-OPEX-2569 | I7: SITE-B | J7: 18700 | K7: =IF(J7="","",ROUND(J7*Settings!$B$3,2)) -> 1309 | L7: =IF(J7="","",J7+K7) -> 20009 | M7: ROUTED | N7: PR-02 | O7: vp_ops | P7: N | R7: ยอดก่อน VAT 18,700 แต่รวม VAT 20,009 → ไป VP ไม่ใช่ DM → ถามลูกค้าว่า DOA นับรวม VAT หรือไม่ | S7: เปลี่ยนนโยบายได้ด้วยการตั้งค่า ไม่ต้องแก้โปรแกรม | T7: Q-02 | U7: 2
A8: 6 | B8: N | C8: ผู้มีอำนาจขอเอง | D8: dm_con | E8: WEB | F8: BUY_GOODS | G8: CON | H8: CON-OPEX-2569 | I8: SITE-A | J8: 16500 | K8: =IF(J8="","",ROUND(J8*Settings!$B$3,2)) -> 1155 | L8: =IF(J8="","",J8+K8) -> 17655 | M8: ROUTED | N8: PR-01 | O8: vp_ops | P8: Y | R8: DM ขอซื้อ 16,500 บาท → ระบบไม่ส่งให้ตัวเอง แต่ยกไป VP พร้อมเหตุผล | S8: กันการอนุมัติตัวเองโดยอัตโนมัติ | T8: Q-03 | U8: 2
A9: 7 | B9: Y | C9: จัดซื้อรวม PR เป็น PO | D9: proc_officer | E9: WEB | K9: =IF(J9="","",ROUND(J9*Settings!$B$3,2)) | L9: =IF(J9="","",J9+K9) | M9: NA | R9: กองรอจัดซื้อเห็นคำขอฉาก 1 กับ H11 (ผู้ขาย S1 ไซต์ A) → รวมเป็น PO เดียว → ส่งอนุมัติ → COO อนุมัติ (PO-01) → ส่งอีเมล PO พร้อม PDF | S9: ลดจำนวน PO และเห็นราคาที่เคยซื้อ | T9: Q-13 | U9: 4
A10: 8 | B10: Y | C10: ตรวจรับหน้างานด้วยมือถือ | D10: receiver_con | E10: LIFF | K10: =IF(J10="","",ROUND(J10*Settings!$B$3,2)) | L10: =IF(J10="","",J10+K10) | M10: NA | R10: เปิดลิงก์ตรวจรับ → รับไม้อัด 60% และ PPE ครบ → ถ่ายรูป → สถานะ PO เป็นรับบางส่วน | S10: หน้างานบันทึกได้ทันทีพร้อมหลักฐาน | T10: Q-28 | U10: 3
A11: 9 | B11: Y | C11: ผู้บริหารเห็นทุกอย่าง | D11: ceo | E11: WEB | K11: =IF(J11="","",ROUND(J11*Settings!$B$3,2)) | L11: =IF(J11="","",J11+K11) | M11: NA | R11: กระดานค้าง (H12 ค้างที่ VP 18 ชม.) → dashboard งบ (ไอทีเหลือ 8%) → KPI สัดส่วนอนุมัติผ่าน LINE → ส่งออก audit พร้อม DOA ref | S11: รู้ทันทีว่างานติดที่ใครและงบไหนใกล้หมด | T11: Q-09 | U11: 3
A12: 10 | B12: N | C12: ลูกค้าแก้ DOA เอง | D12: admin | E12: WEB | K12: =IF(J12="","",ROUND(J12*Settings!$B$3,2)) | L12: =IF(J12="","",J12+K12) | M12: NA | R12: ร่างฉบับ 2 ปรับช่วง DM เป็น 30,000 → เห็น diff และตารางผลที่ขอบ → ส่ง → CEO อนุมัติด้วย PIN → มีผลวันที่ 1 เดือนหน้า → ทดลองส่ง 25,000 เห็นฉบับ 1 ไป VP ฉบับ 2 ไป DM | S12: ลูกค้าดูแลนโยบายเองโดยไม่ต้องรอ BCS และยังมีการตรวจ 4 ตา | T12: Q-06 | U12: 4
A13: 11 | B13: N | C13: รักษาการตอนลา | D13: req_con2 | E13: LIFF | F13: BUY_GOODS | G13: CON | H13: CON-OPEX-2569 | I13: SITE-B | J13: 8000 | K13: =IF(J13="","",ROUND(J13*Settings!$B$3,2)) -> 560 | L13: =IF(J13="","",J13+K13) -> 8560 | M13: ROUTED | N13: PR-01 | O13: asst_con | P13: N | Q13: dm_con>asst_con | R13: dm_con ตั้งรักษาการให้ asst_con ใน LIFF → req_con2 ขอซื้อ 8,000 บาท → งานไป asst_con โดยระบุว่าทำแทน dm_con | S13: งานไม่ค้างตอนผู้อนุมัติลา | T13: Q-05 | U13: 2
A14: 12 | B14: N | C14: เพิ่มผู้ขายด้วยเลขผู้เสียภาษี | D14: proc_officer | E14: WEB | K14: =IF(J14="","",ROUND(J14*Settings!$B$3,2)) | L14: =IF(J14="","",J14+K14) | M14: NA | R14: จัดซื้อเพิ่มผู้ขายใหม่ พิมพ์เลข 13 หลัก → ระบบเติมชื่อ ที่อยู่ สาขา สถานะ VAT และสถานะนิติบุคคลจากสรรพากรและ DBD (demo ใช้โหมด stub หรือบริการจริงตาม registry.mode) | S14: ตรวจตัวตนผู้ขายจากแหล่งของรัฐโดยไม่ต้องใช้ AI | T14: Q-15 | U14: 2
A15: 13 | B15: N | C15: อ่านใบกำกับ e-Tax | D15: fin_officer | E15: WEB | K15: =IF(J15="","",ROUND(J15*Settings!$B$3,2)) | L15: =IF(J15="","",J15+K15) | M15: NA | R15: อัปโหลดไฟล์ e-Tax (PDF/A-3 ที่ฝัง XML) ของ PO ในฉาก 7 → ระบบเติมเลขที่ วันที่ ยอดก่อน VAT และ VAT ให้ยืนยัน → บันทึกแล้วงบย้ายเป็นจ่ายจริง | S15: ฝ่ายบัญชีไม่ต้องพิมพ์ใบกำกับเอง และระบบตรวจ VAT ให้ | T15: Q-35 | U15: 2
T17: รวมนาที | U17: =SUM(U3:U15) -> 34
T18: เฉพาะฉากหลัก | U18: =SUMIFS(U3:U15,B3:B15,"Y") -> 22
A20: แผนสำรอง: ถ้า LINE มีปัญหา เปิดลิงก์ LIFF ในเบราว์เซอร์หรือใช้หน้าอนุมัติบนเว็บ และอัดวิดีโอฉาก 1–3 ไว้ล่วงหน้า
